Workbook

Sheet BSE Start-up
B2: Denessa's Café
B3: Start-up Transactions
C4: Assets | F4: Liabilities | H4: Owners' Equity
B5: Transaction | C5: Cash | D5: Inventory | E5: Fixed Assets | F5: A/P | G5: Credit Card | H5: Contributed Capital | I5: Retained Earnings | J5: Balance Check
B6: Beg Balances
B7: 1. Denessa's Savings | J7: =IF(SUM(C7:E7)=SUM(F7:I7), "OK","ERROR") -> OK
B8: 2. Family Investment | J8: =IF(SUM(C8:E8)=SUM(F8:I8), "OK","ERROR") -> OK
B9: 3. Community Grant | J9: =IF(SUM(C9:E9)=SUM(F9:I9), "OK","ERROR") -> OK | K9: Revenue
B10: 4. Purchase Fixed Assets | J10: =IF(SUM(C10:E10)=SUM(F10:I10), "OK","ERROR") -> OK
B11: 5. Start-up Expenses | J11: =IF(SUM(C11:E11)=SUM(F11:I11), "OK","ERROR") -> OK | K11: Expenses
B12: 6. Inventory Purchase | J12: =IF(SUM(C12:E12)=SUM(F12:I12), "OK","ERROR") -> OK
B13: Ending Balances | C13: =SUM(C6:C12) -> 0 | D13: =SUM(D6:D12) -> 0 | E13: =SUM(E6:E12) -> 0 | F13: =SUM(F6:F12) -> 0 | G13: =SUM(G6:G12) -> 0 | H13: =SUM(H6:H12) -> 0 | I13: =SUM(I6:I12) -> 0 | J13: =IF(SUM(C13:E13)=SUM(F13:I13), "OK","ERROR") -> OK
D14: Total Assets = | E14: =C13+D13+E13 -> 0 | F14: Total Liab. + Equity = | H14: =SUM(F13:I13) -> 0 | J14: =IF(E14-H14-I14=0,"OK","Error") -> OK

Sheet BSE Q1
B2: Denessa's Café
B3: Quarter 1 Transactions
C4: Assets | F4: Liabilities | H4: Owners' Equity
B5: Transaction | C5: Cash | D5: Inventory | E5: Fixed Assets | F5: A/P | G5: Credit Card | H5: Contributed Capital | I5: Retained Earnings | J5: CHECK
B6: Beg Balances | C6: ='BSE Start-up'!C13 -> 0 | D6: ='BSE Start-up'!D13 -> 0 | E6: ='BSE Start-up'!E13 -> 0 | F6: ='BSE Start-up'!F13 -> 0 | G6: ='BSE Start-up'!G13 -> 0 | H6: ='BSE Start-up'!H13 -> 0 | I6: ='BSE Start-up'!I13 -> 0 | J6: =IF(SUM(C6:E6)=SUM(F6:I6), "OK","ERROR") -> OK
B7: 1. Occupancy Expenses | J7: =IF(SUM(C7:E7)=SUM(F7:I7), "OK","ERROR") -> OK | K7: Expenses
B8: 2. Purchase of Food/Beverages | J8: =IF(SUM(C8:E8)=SUM(F8:I8), "OK","ERROR") -> OK
B9: 3. Revenue | J9: =IF(SUM(C9:E9)=SUM(F9:I9), "OK","ERROR") -> OK | K9: Revenue
B10: 4. Cost of Good Sold | J10: =IF(SUM(C10:E10)=SUM(F10:I10), "OK","ERROR") -> OK | K10: COGS
B11: 5. Pay Accounts Payable | J11: =IF(SUM(C11:E11)=SUM(F11:I11), "OK","ERROR") -> OK
B12: 6. Marketing/Administrative Expense | J12: =IF(SUM(C12:E12)=SUM(F12:I12), "OK","ERROR") -> OK | K12: Expenses
B13: 7. Wages | J13: =IF(SUM(C13:E13)=SUM(F13:I13), "OK","ERROR") -> OK | K13: Espenses
B14: 8. Credit Card Interest Expense | J14: =IF(SUM(C14:E14)=SUM(F14:I14), "OK","ERROR") -> OK | K14: Interest expense
B15: Ending Balances | C15: =SUM(C6:C14) -> 0 | D15: =SUM(D6:D14) -> 0 | E15: =SUM(E6:E14) -> 0 | F15: =SUM(F6:F14) -> 0 | G15: =SUM(G6:G14) -> 0 | H15: =SUM(H6:H14) -> 0 | I15: =SUM(I6:I14) -> 0 | J15: =IF(SUM(C15:E15)=SUM(F15:I15), "OK","ERROR") -> OK
D16: Total Assets = | E16: =SUM(C15:E15) -> 0 | F16: Total Liab. + Equity = | H16: =SUM(F15:I15) -> 0 | J16: =IF(SUM(C16:E16)=SUM(F16:I16), "OK","ERROR") -> OK
B20: Income Statement | C20: Q1
B21: Revenue
B22: Cost of Goods Sold
B23: Gross Profit | C23: =C21+C22 -> 0
B24: Occupancy Expenses
B25: Marketing/Admin. Expense
B26: Wages
B27: Total Operating Expenses | C27: =SUM(C24:C26) -> 0
B28: Operating Profit | C28: =C23+C27 -> 0
B29: Interest Expense
B30: Pre-tax Profit | C30: =C28+C29 -> 0 | D30: =IF(C30=250,"CORRECT!","NOT QUITE...TRY AGAIN") -> NOT QUITE...TRY AGAIN
B34: Balance Sheet | C34: Q1
B35: Assets
B36: Cash
B37: Inventory
B38: Current Assets | C38: =C36+C37 -> 0
B39: Fixed Assets
B40: Total Assets | C40: =C38+C39 -> 0
B41: Liabilities
B42: Accounts Payable
B43: Credit Card
B44: Current Liabilities | C44: =C42+C43 -> 0
B45: Owners Equity
B46: Contributed Capital
B47: Retained Earnings
...
